
C:\Users\ccadenc\Desktop\pythonstuff\PythonDjango\users>RUN: 'python manage.py shell'
'RUN:' is not recognized as an internal or external command,
operable program or batch file.

C:\Users\ccadenc\Desktop\pythonstuff\PythonDjango\users>python manage.py shell
Traceback (most recent call last):
  File "manage.py", line 22, in <module>
    execute_from_command_line(sys.argv)
  File "C:\Python27\lib\site-packages\django\core\management\__init__.py", line 364, in execute_from_command_line
    utility.execute()
  File "C:\Python27\lib\site-packages\django\core\management\__init__.py", line 338, in execute
    django.setup()
  File "C:\Python27\lib\site-packages\django\__init__.py", line 27, in setup
    apps.populate(settings.INSTALLED_APPS)
  File "C:\Python27\lib\site-packages\django\apps\registry.py", line 85, in populate
    app_config = AppConfig.create(entry)
  File "C:\Python27\lib\site-packages\django\apps\config.py", line 94, in create
    module = import_module(entry)
  File "C:\Python27\lib\importlib\__init__.py", line 37, in import_module
    __import__(name)
  File "C:\Users\ccadenc\Desktop\pythonstuff\PythonDjango\users\apps\__init__.py", line 1
    1 file(s) copied.
    ^
IndentationError: unexpected indent

C:\Users\ccadenc\Desktop\pythonstuff\PythonDjango\users>python manage.py shell
Traceback (most recent call last):
  File "manage.py", line 22, in <module>
    execute_from_command_line(sys.argv)
  File "C:\Python27\lib\site-packages\django\core\management\__init__.py", line 364, in execute_from_command_line
    utility.execute()
  File "C:\Python27\lib\site-packages\django\core\management\__init__.py", line 338, in execute
    django.setup()
  File "C:\Python27\lib\site-packages\django\__init__.py", line 27, in setup
    apps.populate(settings.INSTALLED_APPS)
  File "C:\Python27\lib\site-packages\django\apps\registry.py", line 85, in populate
    app_config = AppConfig.create(entry)
  File "C:\Python27\lib\site-packages\django\apps\config.py", line 94, in create
    module = import_module(entry)
  File "C:\Python27\lib\importlib\__init__.py", line 37, in import_module
    __import__(name)
  File "C:\Users\ccadenc\Desktop\pythonstuff\PythonDjango\users\apps\__init__.py", line 1
    1 file(s) copied.
    ^
IndentationError: unexpected indent

C:\Users\ccadenc\Desktop\pythonstuff\PythonDjango\users>python manage.py shell
Traceback (most recent call last):
  File "manage.py", line 22, in <module>
    execute_from_command_line(sys.argv)
  File "C:\Python27\lib\site-packages\django\core\management\__init__.py", line 364, in execute_from_command_line
    utility.execute()
  File "C:\Python27\lib\site-packages\django\core\management\__init__.py", line 338, in execute
    django.setup()
  File "C:\Python27\lib\site-packages\django\__init__.py", line 27, in setup
    apps.populate(settings.INSTALLED_APPS)
  File "C:\Python27\lib\site-packages\django\apps\registry.py", line 85, in populate
    app_config = AppConfig.create(entry)
  File "C:\Python27\lib\site-packages\django\apps\config.py", line 120, in create
    mod = import_module(mod_path)
  File "C:\Python27\lib\importlib\__init__.py", line 37, in import_module
    __import__(name)
ImportError: No module named suers_appdjango.contrib

C:\Users\ccadenc\Desktop\pythonstuff\PythonDjango\users>python manage.py shell
Traceback (most recent call last):
  File "manage.py", line 22, in <module>
    execute_from_command_line(sys.argv)
  File "C:\Python27\lib\site-packages\django\core\management\__init__.py", line 364, in execute_from_command_line
    utility.execute()
  File "C:\Python27\lib\site-packages\django\core\management\__init__.py", line 338, in execute
    django.setup()
  File "C:\Python27\lib\site-packages\django\__init__.py", line 27, in setup
    apps.populate(settings.INSTALLED_APPS)
  File "C:\Python27\lib\site-packages\django\apps\registry.py", line 85, in populate
    app_config = AppConfig.create(entry)
  File "C:\Python27\lib\site-packages\django\apps\config.py", line 120, in create
    mod = import_module(mod_path)
  File "C:\Python27\lib\importlib\__init__.py", line 37, in import_module
    __import__(name)
ImportError: No module named suers_appdjango.contrib

C:\Users\ccadenc\Desktop\pythonstuff\PythonDjango\users>python manage.py shell
Traceback (most recent call last):
  File "manage.py", line 22, in <module>
    execute_from_command_line(sys.argv)
  File "C:\Python27\lib\site-packages\django\core\management\__init__.py", line 364, in execute_from_command_line
    utility.execute()
  File "C:\Python27\lib\site-packages\django\core\management\__init__.py", line 338, in execute
    django.setup()
  File "C:\Python27\lib\site-packages\django\__init__.py", line 27, in setup
    apps.populate(settings.INSTALLED_APPS)
  File "C:\Python27\lib\site-packages\django\apps\registry.py", line 85, in populate
    app_config = AppConfig.create(entry)
  File "C:\Python27\lib\site-packages\django\apps\config.py", line 120, in create
    mod = import_module(mod_path)
  File "C:\Python27\lib\importlib\__init__.py", line 37, in import_module
    __import__(name)
ImportError: No module named users_appdjango.contrib

C:\Users\ccadenc\Desktop\pythonstuff\PythonDjango\users>python manage.py shell
Traceback (most recent call last):
  File "manage.py", line 22, in <module>
    execute_from_command_line(sys.argv)
  File "C:\Python27\lib\site-packages\django\core\management\__init__.py", line 364, in execute_from_command_line
    utility.execute()
  File "C:\Python27\lib\site-packages\django\core\management\__init__.py", line 338, in execute
    django.setup()
  File "C:\Python27\lib\site-packages\django\__init__.py", line 27, in setup
    apps.populate(settings.INSTALLED_APPS)
  File "C:\Python27\lib\site-packages\django\apps\registry.py", line 108, in populate
    app_config.import_models()
  File "C:\Python27\lib\site-packages\django\apps\config.py", line 202, in import_models
    self.models_module = import_module(models_module_name)
  File "C:\Python27\lib\importlib\__init__.py", line 37, in import_module
    __import__(name)
  File "C:\Users\ccadenc\Desktop\pythonstuff\PythonDjango\users\apps\users_app\models.py", line 11
    last)_name=models.CharField(max_length = 255)
        ^
SyntaxError: invalid syntax

C:\Users\ccadenc\Desktop\pythonstuff\PythonDjango\users>python manage.py shell
Python 2.7.13 (v2.7.13:a06454b1afa1, Dec 17 2016, 20:53:40) [MSC v.1500 64 bit (AMD64)] on win32
Type "help", "copyright", "credits" or "license" for more information.
(InteractiveConsole)
>>> from apps.user_app.models import User
Traceback (most recent call last):
  File "<console>", line 1, in <module>
ImportError: No module named user_app.models
>>> from apps.user_app.migratins.models import User
Traceback (most recent call last):
  File "<console>", line 1, in <module>
ImportError: No module named user_app.migratins.models
>>> from apps.users_app.models import Users
Traceback (most recent call last):
  File "<console>", line 1, in <module>
ImportError: cannot import name Users
>>> from apps.users_apps import User
Traceback (most recent call last):
  File "<console>", line 1, in <module>
ImportError: No module named users_apps
>>> from apps.users_app.models import User
>>> User.objects.create(first_name="Michael", last_name="Jordan", email="mike@jumpman.com", age=23)
Traceback (most recent call last):
  File "<console>", line 1, in <module>
  File "C:\Python27\lib\site-packages\django\db\models\manager.py", line 85, in manager_method
    return getattr(self.get_queryset(), name)(*args, **kwargs)
  File "C:\Python27\lib\site-packages\django\db\models\query.py", line 394, in create
    obj.save(force_insert=True, using=self.db)
  File "C:\Python27\lib\site-packages\django\db\models\base.py", line 808, in save
    force_update=force_update, update_fields=update_fields)
  File "C:\Python27\lib\site-packages\django\db\models\base.py", line 838, in save_base
    updated = self._save_table(raw, cls, force_insert, force_update, using, update_fields)
  File "C:\Python27\lib\site-packages\django\db\models\base.py", line 924, in _save_table
    result = self._do_insert(cls._base_manager, using, fields, update_pk, raw)
  File "C:\Python27\lib\site-packages\django\db\models\base.py", line 963, in _do_insert
    using=using, raw=raw)
  File "C:\Python27\lib\site-packages\django\db\models\manager.py", line 85, in manager_method
    return getattr(self.get_queryset(), name)(*args, **kwargs)
  File "C:\Python27\lib\site-packages\django\db\models\query.py", line 1076, in _insert
    return query.get_compiler(using=using).execute_sql(return_id)
  File "C:\Python27\lib\site-packages\django\db\models\sql\compiler.py", line 1107, in execute_sql
    cursor.execute(sql, params)
  File "C:\Python27\lib\site-packages\django\db\backends\utils.py", line 80, in execute
    return super(CursorDebugWrapper, self).execute(sql, params)
  File "C:\Python27\lib\site-packages\django\db\backends\utils.py", line 65, in execute
    return self.cursor.execute(sql, params)
  File "C:\Python27\lib\site-packages\django\db\utils.py", line 94, in __exit__
    six.reraise(dj_exc_type, dj_exc_value, traceback)
  File "C:\Python27\lib\site-packages\django\db\backends\utils.py", line 65, in execute
    return self.cursor.execute(sql, params)
  File "C:\Python27\lib\site-packages\django\db\backends\sqlite3\base.py", line 328, in execute
    return Database.Cursor.execute(self, query, params)
OperationalError: no such table: users_app_user
>>> User.objects.create(first_name="bunny", last_name="Cha", email="rabbits@gmail.com", age=2)
Traceback (most recent call last):
  File "<console>", line 1, in <module>
  File "C:\Python27\lib\site-packages\django\db\models\manager.py", line 85, in manager_method
    return getattr(self.get_queryset(), name)(*args, **kwargs)
  File "C:\Python27\lib\site-packages\django\db\models\query.py", line 394, in create
    obj.save(force_insert=True, using=self.db)
  File "C:\Python27\lib\site-packages\django\db\models\base.py", line 808, in save
    force_update=force_update, update_fields=update_fields)
  File "C:\Python27\lib\site-packages\django\db\models\base.py", line 838, in save_base
    updated = self._save_table(raw, cls, force_insert, force_update, using, update_fields)
  File "C:\Python27\lib\site-packages\django\db\models\base.py", line 924, in _save_table
    result = self._do_insert(cls._base_manager, using, fields, update_pk, raw)
  File "C:\Python27\lib\site-packages\django\db\models\base.py", line 963, in _do_insert
    using=using, raw=raw)
  File "C:\Python27\lib\site-packages\django\db\models\manager.py", line 85, in manager_method
    return getattr(self.get_queryset(), name)(*args, **kwargs)
  File "C:\Python27\lib\site-packages\django\db\models\query.py", line 1076, in _insert
    return query.get_compiler(using=using).execute_sql(return_id)
  File "C:\Python27\lib\site-packages\django\db\models\sql\compiler.py", line 1107, in execute_sql
    cursor.execute(sql, params)
  File "C:\Python27\lib\site-packages\django\db\backends\utils.py", line 80, in execute
    return super(CursorDebugWrapper, self).execute(sql, params)
  File "C:\Python27\lib\site-packages\django\db\backends\utils.py", line 65, in execute
    return self.cursor.execute(sql, params)
  File "C:\Python27\lib\site-packages\django\db\utils.py", line 94, in __exit__
    six.reraise(dj_exc_type, dj_exc_value, traceback)
  File "C:\Python27\lib\site-packages\django\db\backends\utils.py", line 65, in execute
    return self.cursor.execute(sql, params)
  File "C:\Python27\lib\site-packages\django\db\backends\sqlite3\base.py", line 328, in execute
    return Database.Cursor.execute(self, query, params)
OperationalError: no such table: users_app_user
>>>
